<?xml version="1.0" ?>
<!-- =================================================================================== -->
<!-- |    This document was autogenerated by xacro from rb10_1300e.urdf.xacro          | -->
<!-- |    EDITING THIS FILE BY HAND IS NOT RECOMMENDED                                 | -->
<!-- =================================================================================== -->
<robot name="dual_rb10_1300e">
  <!-- source side manipulator -->
  <link name="base_support"/>
  
  <link name="link0_source">
    <visual>
      <geometry>
        <mesh filename="package://dual_rb10_description/meshes/rb10_1300e/visual/link0.dae"/>
      </geometry>
    </visual>
    <collision>
      <geometry>
        <mesh filename="package://dual_rb10_description/meshes/rb10_1300e/collision/link0.stl"/>
      </geometry>
    </collision>
  </link>
  <link name="link1_source">
    <visual>
      <geometry>
        <mesh filename="package://dual_rb10_description/meshes/rb10_1300e/visual/link1.dae"/>
      </geometry>
    </visual>
    <collision>
      <geometry>
        <mesh filename="package://dual_rb10_description/meshes/rb10_1300e/collision/link1.stl"/>
      </geometry>
    </collision>
    <inertial>
      <origin rpy="0 0 0" xyz="0.000021 -0.007855 -0.042537"/>
      <mass value="8.366"/>
      <inertia ixx="0.027403652" ixy="-5.926e-06" ixz="-1.0119e-05" iyy="0.027770573" iyz="0.003030512" izz="0.026140211"/>
    </inertial>
  </link>
  <link name="link2_source">
    <visual>
      <geometry>
        <mesh filename="package://dual_rb10_description/meshes/rb10_1300e/visual/link2.dae"/>
      </geometry>
    </visual>
    <collision>
      <geometry>
        <mesh filename="package://dual_rb10_description/meshes/rb10_1300e/collision/link2.stl"/>
      </geometry>
    </collision>
    <inertial>
      <origin rpy="0 0 0" xyz="-0.000013 -0.155462 0.225241"/>
      <mass value="15.61"/>
      <inertia ixx="1.140650644" ixy="-1.3042e-05" ixz="-6.7084e-05" iyy="1.134398623" iyz="0.024507884" izz="0.050849068"/>
    </inertial>
  </link>
  <link name="link3_source">
    <visual>
      <geometry>
        <mesh filename="package://dual_rb10_description/meshes/rb10_1300e/visual/link3.dae"/>
      </geometry>
    </visual>
    <collision>
      <geometry>
        <mesh filename="package://dual_rb10_description/meshes/rb10_1300e/collision/link3.stl"/>
      </geometry>
    </collision>
    <inertial>
      <origin rpy="0 0 0" xyz="-0.000048 -0.013885 0.325013"/>
      <mass value="5.69"/>
      <inertia ixx="0.312033029" ixy="9.298e-06" ixz="1.169e-05" iyy="0.311287646" iyz="0.005331552" izz="0.011397824"/>
    </inertial>
  </link>
  <link name="link4_source">
    <visual>
      <geometry>
        <mesh filename="package://dual_rb10_description/meshes/rb10_1300e/visual/link4.dae"/>
      </geometry>
    </visual>
    <collision>
      <geometry>
        <mesh filename="package://dual_rb10_description/meshes/rb10_1300e/collision/link4.stl"/>
      </geometry>
    </collision>
    <inertial>
      <origin rpy="0 0 0" xyz="0.000093 -0.113949 0.026461"/>
      <mass value="2.062"/>
      <inertia ixx="0.0027111" ixy="-8.022e-06" ixz="1.1208e-05" iyy="0.002715407" iyz="0.000144243" izz="0.002157043"/>
    </inertial>
  </link>
  <link name="link5_source">
    <visual>
      <geometry>
        <mesh filename="package://dual_rb10_description/meshes/rb10_1300e/visual/link5.dae"/>
      </geometry>
    </visual>
    <collision>
      <geometry>
        <mesh filename="package://dual_rb10_description/meshes/rb10_1300e/collision/link5.stl"/>
      </geometry>
    </collision>
    <inertial>
      <origin rpy="0 0 0" xyz="-0.000093 -0.026434 -0.003233"/>
      <mass value="2.061"/>
      <inertia ixx="0.002706437" ixy="1.1205e-05" ixz="-8.016e-06" iyy="0.002153592" iyz="0.000141528" izz="0.002712272"/>
    </inertial>
  </link>
  <link name="link6_source">
    <visual>
      <geometry>
        <mesh filename="package://dual_rb10_description/meshes/rb10_1300e/visual/link6.dae"/>
      </geometry>
    </visual>
    <collision>
      <geometry>
        <mesh filename="package://dual_rb10_description/meshes/rb10_1300e/collision/link6.stl"/>
      </geometry>
    </collision>
    <inertial>
      <origin rpy="0 0 0" xyz="-0.000210 -0.092540 -0.000292"/>
      <mass value="0.406"/>
      <inertia ixx="0.000345314" ixy="5.73e-07" ixz="6.61e-07" iyy="0.000532873" iyz="-5.4e-08" izz="0.000340021"/>
    </inertial>
  </link>
  <link name="tcp_source"/>

  <joint name="base_support_source" type="fixed">
    <parent link="base_support"/>
    <child link="link0_source"/>
    <origin xyz="0.5 0 0"/>
  </joint>
  <joint name="base_source" type="revolute">
    <origin rpy="0 0 0" xyz="0 0 0.197"/>
    <parent link="link0_source"/>
    <child link="link1_source"/>
    <axis xyz="0 0 1"/>
    <limit effort="10" lower="-3.14" upper="3.14" velocity="3.14"/>
  </joint>
  <joint name="shoulder_source" type="revolute">
    <origin rpy="0 0 0" xyz="0 -0.1875 0"/>
    <parent link="link1_source"/>
    <child link="link2_source"/>
    <axis xyz="0 1 0"/>
    <limit effort="10" lower="-3.14" upper="3.14" velocity="3.14"/>
  </joint>
  <joint name="elbow_source" type="revolute">
    <origin rpy="0 0 0" xyz="0 0 0.6127"/>
    <parent link="link2_source"/>
    <child link="link3_source"/>
    <axis xyz="0 1 0"/>
    <limit effort="10" lower="-3.14" upper="3.14" velocity="3.14"/>
  </joint>
  <joint name="wrist1_source" type="revolute">
    <origin rpy="0 0 0" xyz="0 0.11715 0.57015"/>
    <parent link="link3_source"/>
    <child link="link4_source"/>
    <axis xyz="0 1 0"/>
    <limit effort="10" lower="-3.14" upper="3.14" velocity="3.14"/>
  </joint>
  <joint name="wrist2_source" type="revolute">
    <origin rpy="0 0 0" xyz="0 -0.11715 0"/>
    <parent link="link4_source"/>
    <child link="link5_source"/>
    <axis xyz="0 0 1"/>
    <limit effort="10" lower="-3.14" upper="3.14" velocity="3.14"/>
  </joint>
  <joint name="wrist3_source" type="revolute">
    <origin rpy="0 0 0" xyz="0 0 0.11715"/>
    <parent link="link5_source"/>
    <child link="link6_source"/>
    <axis xyz="0 1 0"/>
    <limit effort="10" lower="-3.14" upper="3.14" velocity="3.14"/>
  </joint>
  <joint name="tcp_joint_source" type="fixed">
    <origin rpy="0 0 0" xyz="0 -0.1153 0"/>
    <parent link="link6_source"/>
    <child link="tcp_source"/>
  </joint>
  <ros2_control name="RBPodoHardwareInterface" type="system">
    <hardware>
      <plugin>mock_components/GenericSystem</plugin>
      <param name="mock_sensor_commands">False</param>
      <param name="state_following_offset">0.0</param>
    </hardware>
    <joint name="base_source">
      <param name="initial_position">0.0</param>
      <param name="torque_constant">1</param>
      <command_interface name="effort"/>
      <command_interface name="velocity"/>
      <command_interface name="position"/>
      <state_interface name="position"/>
      <state_interface name="effort"/>
    </joint>
    <joint name="shoulder_source">
      <param name="initial_position">0.0</param>
      <param name="torque_constant">1</param>
      <command_interface name="effort"/>
      <command_interface name="velocity"/>
      <command_interface name="position"/>
      <state_interface name="position"/>
      <state_interface name="effort"/>
    </joint>
    <joint name="elbow_source">
      <param name="initial_position">0.0</param>
      <param name="torque_constant">1</param>
      <command_interface name="effort"/>
      <command_interface name="velocity"/>
      <command_interface name="position"/>
      <state_interface name="position"/>
      <state_interface name="effort"/>
    </joint>
    <joint name="wrist1_source">
      <param name="initial_position">0.0</param>
      <param name="torque_constant">1</param>
      <command_interface name="effort"/>
      <command_interface name="velocity"/>
      <command_interface name="position"/>
      <state_interface name="position"/>
      <state_interface name="effort"/>
    </joint>
    <joint name="wrist2_source">
      <param name="initial_position">0.0</param>
      <param name="torque_constant">1</param>
      <command_interface name="effort"/>
      <command_interface name="velocity"/>
      <command_interface name="position"/>
      <state_interface name="position"/>
      <state_interface name="effort"/>
    </joint>
    <joint name="wrist3_source">
      <param name="initial_position">0.0</param>
      <param name="torque_constant">1</param>
      <command_interface name="effort"/>
      <command_interface name="velocity"/>
      <command_interface name="position"/>
      <state_interface name="position"/>
      <state_interface name="effort"/>
    </joint>
  </ros2_control>

  <!-- detector side manipulator -->
  <link name="link0_detector">
    <visual>
      <geometry>
        <mesh filename="package://dual_rb10_description/meshes/rb10_1300e/visual/link0.dae"/>
      </geometry>
    </visual>
    <collision>
      <geometry>
        <mesh filename="package://dual_rb10_description/meshes/rb10_1300e/collision/link0.stl"/>
      </geometry>
    </collision>
  </link>
  <link name="link1_detector">
    <visual>
      <geometry>
        <mesh filename="package://dual_rb10_description/meshes/rb10_1300e/visual/link1.dae"/>
      </geometry>
    </visual>
    <collision>
      <geometry>
        <mesh filename="package://dual_rb10_description/meshes/rb10_1300e/collision/link1.stl"/>
      </geometry>
    </collision>
    <inertial>
      <origin rpy="0 0 0" xyz="0.000021 -0.007855 -0.042537"/>
      <mass value="8.366"/>
      <inertia ixx="0.027403652" ixy="-5.926e-06" ixz="-1.0119e-05" iyy="0.027770573" iyz="0.003030512" izz="0.026140211"/>
    </inertial>
  </link>
  <link name="link2_detector">
    <visual>
      <geometry>
        <mesh filename="package://dual_rb10_description/meshes/rb10_1300e/visual/link2.dae"/>
      </geometry>
    </visual>
    <collision>
      <geometry>
        <mesh filename="package://dual_rb10_description/meshes/rb10_1300e/collision/link2.stl"/>
      </geometry>
    </collision>
    <inertial>
      <origin rpy="0 0 0" xyz="-0.000013 -0.155462 0.225241"/>
      <mass value="15.61"/>
      <inertia ixx="1.140650644" ixy="-1.3042e-05" ixz="-6.7084e-05" iyy="1.134398623" iyz="0.024507884" izz="0.050849068"/>
    </inertial>
  </link>
  <link name="link3_detector">
    <visual>
      <geometry>
        <mesh filename="package://dual_rb10_description/meshes/rb10_1300e/visual/link3.dae"/>
      </geometry>
    </visual>
    <collision>
      <geometry>
        <mesh filename="package://dual_rb10_description/meshes/rb10_1300e/collision/link3.stl"/>
      </geometry>
    </collision>
    <inertial>
      <origin rpy="0 0 0" xyz="-0.000048 -0.013885 0.325013"/>
      <mass value="5.69"/>
      <inertia ixx="0.312033029" ixy="9.298e-06" ixz="1.169e-05" iyy="0.311287646" iyz="0.005331552" izz="0.011397824"/>
    </inertial>
  </link>
  <link name="link4_detector">
    <visual>
      <geometry>
        <mesh filename="package://dual_rb10_description/meshes/rb10_1300e/visual/link4.dae"/>
      </geometry>
    </visual>
    <collision>
      <geometry>
        <mesh filename="package://dual_rb10_description/meshes/rb10_1300e/collision/link4.stl"/>
      </geometry>
    </collision>
    <inertial>
      <origin rpy="0 0 0" xyz="0.000093 -0.113949 0.026461"/>
      <mass value="2.062"/>
      <inertia ixx="0.0027111" ixy="-8.022e-06" ixz="1.1208e-05" iyy="0.002715407" iyz="0.000144243" izz="0.002157043"/>
    </inertial>
  </link>
  <link name="link5_detector">
    <visual>
      <geometry>
        <mesh filename="package://dual_rb10_description/meshes/rb10_1300e/visual/link5.dae"/>
      </geometry>
    </visual>
    <collision>
      <geometry>
        <mesh filename="package://dual_rb10_description/meshes/rb10_1300e/collision/link5.stl"/>
      </geometry>
    </collision>
    <inertial>
      <origin rpy="0 0 0" xyz="-0.000093 -0.026434 -0.003233"/>
      <mass value="2.061"/>
      <inertia ixx="0.002706437" ixy="1.1205e-05" ixz="-8.016e-06" iyy="0.002153592" iyz="0.000141528" izz="0.002712272"/>
    </inertial>
  </link>
  <link name="link6_detector">
    <visual>
      <geometry>
        <mesh filename="package://dual_rb10_description/meshes/rb10_1300e/visual/link6.dae"/>
      </geometry>
    </visual>
    <collision>
      <geometry>
        <mesh filename="package://dual_rb10_description/meshes/rb10_1300e/collision/link6.stl"/>
      </geometry>
    </collision>
    <inertial>
      <origin rpy="0 0 0" xyz="-0.000210 -0.092540 -0.000292"/>
      <mass value="0.406"/>
      <inertia ixx="0.000345314" ixy="5.73e-07" ixz="6.61e-07" iyy="0.000532873" iyz="-5.4e-08" izz="0.000340021"/>
    </inertial>
  </link>
  <link name="tcp_detector"/>
  <joint name="base_support_detector" type="fixed">
    <parent link="base_support"/>
    <child link="link0_detector"/>
    <origin xyz="-0.5 0 0"/>
  </joint>
  <joint name="base_detector" type="revolute">
    <origin rpy="0 0 0" xyz="0 0 0.197"/>
    <parent link="link0_detector"/>
    <child link="link1_detector"/>
    <axis xyz="0 0 1"/>
    <limit effort="10" lower="-3.14" upper="3.14" velocity="3.14"/>
  </joint>
  <joint name="shoulder_detector" type="revolute">
    <origin rpy="0 0 0" xyz="0 -0.1875 0"/>
    <parent link="link1_detector"/>
    <child link="link2_detector"/>
    <axis xyz="0 1 0"/>
    <limit effort="10" lower="-3.14" upper="3.14" velocity="3.14"/>
  </joint>
  <joint name="elbow_detector" type="revolute">
    <origin rpy="0 0 0" xyz="0 0 0.6127"/>
    <parent link="link2_detector"/>
    <child link="link3_detector"/>
    <axis xyz="0 1 0"/>
    <limit effort="10" lower="-3.14" upper="3.14" velocity="3.14"/>
  </joint>
  <joint name="wrist1_detector" type="revolute">
    <origin rpy="0 0 0" xyz="0 0.11715 0.57015"/>
    <parent link="link3_detector"/>
    <child link="link4_detector"/>
    <axis xyz="0 1 0"/>
    <limit effort="10" lower="-3.14" upper="3.14" velocity="3.14"/>
  </joint>
  <joint name="wrist2_detector" type="revolute">
    <origin rpy="0 0 0" xyz="0 -0.11715 0"/>
    <parent link="link4_detector"/>
    <child link="link5_detector"/>
    <axis xyz="0 0 1"/>
    <limit effort="10" lower="-3.14" upper="3.14" velocity="3.14"/>
  </joint>
  <joint name="wrist3_detector" type="revolute">
    <origin rpy="0 0 0" xyz="0 0 0.11715"/>
    <parent link="link5_detector"/>
    <child link="link6_detector"/>
    <axis xyz="0 1 0"/>
    <limit effort="10" lower="-3.14" upper="3.14" velocity="3.14"/>
  </joint>
  <joint name="tcp_joint_detector" type="fixed">
    <origin rpy="0 0 0" xyz="0 -0.1153 0"/>
    <parent link="link6_detector"/>
    <child link="tcp_detector"/>
  </joint>
  <ros2_control name="RBPodoHardwareInterface" type="system">
    <hardware>
      <plugin>mock_components/GenericSystem</plugin>
      <param name="mock_sensor_commands">False</param>
      <param name="state_following_offset">0.0</param>
    </hardware>
    <joint name="base_detector">
      <param name="initial_position">0.0</param>
      <param name="torque_constant">1</param>
      <command_interface name="effort"/>
      <command_interface name="velocity"/>
      <command_interface name="position"/>
      <state_interface name="position"/>
      <state_interface name="effort"/>
    </joint>
    <joint name="shoulder_detector">
      <param name="initial_position">0.0</param>
      <param name="torque_constant">1</param>
      <command_interface name="effort"/>
      <command_interface name="velocity"/>
      <command_interface name="position"/>
      <state_interface name="position"/>
      <state_interface name="effort"/>
    </joint>
    <joint name="elbow_detector">
      <param name="initial_position">0.0</param>
      <param name="torque_constant">1</param>
      <command_interface name="effort"/>
      <command_interface name="velocity"/>
      <command_interface name="position"/>
      <state_interface name="position"/>
      <state_interface name="effort"/>
    </joint>
    <joint name="wrist1_detector">
      <param name="initial_position">0.0</param>
      <param name="torque_constant">1</param>
      <command_interface name="effort"/>
      <command_interface name="velocity"/>
      <command_interface name="position"/>
      <state_interface name="position"/>
      <state_interface name="effort"/>
    </joint>
    <joint name="wrist2_detector">
      <param name="initial_position">0.0</param>
      <param name="torque_constant">1</param>
      <command_interface name="effort"/>
      <command_interface name="velocity"/>
      <command_interface name="position"/>
      <state_interface name="position"/>
      <state_interface name="effort"/>
    </joint>
    <joint name="wrist3_detector">
      <param name="initial_position">0.0</param>
      <param name="torque_constant">1</param>
      <command_interface name="effort"/>
      <command_interface name="velocity"/>
      <command_interface name="position"/>
      <state_interface name="position"/>
      <state_interface name="effort"/>
    </joint>
  </ros2_control>
</robot>
