#VRML_SIM R2025a utf8
# license: Apache License 2.0
# license url: http://www.apache.org/licenses/LICENSE-2.0
# This is a proto file for Webots for the Rb101300e
# Extracted from: /home/dev/dev/webots/rbpodo_ros2/rbpodo_description/robots/rb10_1300e.urdf

PROTO Rb101300e [
  field  SFVec3f     translation     0 0 0
  field  SFRotation  rotation        0 0 1 0
  field  SFString    name            "Rb101300e"  # Is `Robot.name`.
  field  SFString    controller      "void"       # Is `Robot.controller`.
  field  MFString    controllerArgs  []           # Is `Robot.controllerArgs`.
  field  SFString    customData      ""           # Is `Robot.customData`.
  field  SFBool      supervisor      FALSE        # Is `Robot.supervisor`.
  field  SFBool      synchronization TRUE         # Is `Robot.synchronization`.
  field  SFBool      selfCollision   FALSE        # Is `Robot.selfCollision`.
  field  MFNode      toolSlot        []           # Extend the robot with new nodes at the end of the arm.
]
{
  Robot {
    translation IS translation
    rotation IS rotation
    controller IS controller
    controllerArgs IS controllerArgs
    customData IS customData
    supervisor IS supervisor
    synchronization IS synchronization
    selfCollision IS selfCollision
    children [
      DEF link0_visual CadShape {
        url "/home/dev/dev/webots/rbpodo_ros2/rbpodo_description/meshes/rb10_1300e/visual/link0.dae"
      }
      HingeJoint {
        jointParameters HingeJointParameters {
          axis 0.000000 0.000000 1.000000
          anchor 0.000000 0.000000 0.197000
        }
        device [
          RotationalMotor {
            name "base"
            maxVelocity 3.14
            minPosition -3.14
            maxPosition 3.14
            maxTorque 10.0
          }
          PositionSensor {
            name "base_sensor"
          }
        ]
        endPoint Solid {
          translation 0.000000 0.000000 0.197000
          children [
            DEF link1_visual CadShape {
              url "/home/dev/dev/webots/rbpodo_ros2/rbpodo_description/meshes/rb10_1300e/visual/link1.dae"
            }
            HingeJoint {
              jointParameters HingeJointParameters {
                axis 0.000000 1.000000 0.000000
                anchor 0.000000 -0.187500 0.000000
              }
              device [
                RotationalMotor {
                  name "shoulder"
                  maxVelocity 3.14
                  minPosition -3.14
                  maxPosition 3.14
                  maxTorque 10.0
                }
                PositionSensor {
                  name "shoulder_sensor"
                }
              ]
              endPoint Solid {
                translation 0.000000 -0.187500 0.000000
                children [
                  DEF link2_visual CadShape {
                    url "/home/dev/dev/webots/rbpodo_ros2/rbpodo_description/meshes/rb10_1300e/visual/link2.dae"
                  }
                  HingeJoint {
                    jointParameters HingeJointParameters {
                      axis 0.000000 1.000000 0.000000
                      anchor 0.000000 0.000000 0.612700
                    }
                    device [
                      RotationalMotor {
                        name "elbow"
                        maxVelocity 3.14
                        minPosition -3.14
                        maxPosition 3.14
                        maxTorque 10.0
                      }
                      PositionSensor {
                        name "elbow_sensor"
                      }
                    ]
                    endPoint Solid {
                      translation 0.000000 0.000000 0.612700
                      children [
                        DEF link3_visual CadShape {
                          url "/home/dev/dev/webots/rbpodo_ros2/rbpodo_description/meshes/rb10_1300e/visual/link3.dae"
                        }
                        HingeJoint {
                          jointParameters HingeJointParameters {
                            axis 0.000000 1.000000 0.000000
                            anchor 0.000000 0.117150 0.570150
                          }
                          device [
                            RotationalMotor {
                              name "wrist1"
                              maxVelocity 3.14
                              minPosition -3.14
                              maxPosition 3.14
                              maxTorque 10.0
                            }
                            PositionSensor {
                              name "wrist1_sensor"
                            }
                          ]
                          endPoint Solid {
                            translation 0.000000 0.117150 0.570150
                            children [
                              DEF link4_visual CadShape {
                                url "/home/dev/dev/webots/rbpodo_ros2/rbpodo_description/meshes/rb10_1300e/visual/link4.dae"
                              }
                              HingeJoint {
                                jointParameters HingeJointParameters {
                                  axis 0.000000 0.000000 1.000000
                                  anchor 0.000000 -0.117150 0.000000
                                }
                                device [
                                  RotationalMotor {
                                    name "wrist2"
                                    maxVelocity 3.14
                                    minPosition -3.14
                                    maxPosition 3.14
                                    maxTorque 10.0
                                  }
                                  PositionSensor {
                                    name "wrist2_sensor"
                                  }
                                ]
                                endPoint Solid {
                                  translation 0.000000 -0.117150 0.000000
                                  children [
                                    DEF link5_visual CadShape {
                                      url "/home/dev/dev/webots/rbpodo_ros2/rbpodo_description/meshes/rb10_1300e/visual/link5.dae"
                                    }
                                    HingeJoint {
                                      jointParameters HingeJointParameters {
                                        axis 0.000000 1.000000 0.000000
                                        anchor 0.000000 0.000000 0.117150
                                      }
                                      device [
                                        RotationalMotor {
                                          name "wrist3"
                                          maxVelocity 3.14
                                          minPosition -3.14
                                          maxPosition 3.14
                                          maxTorque 10.0
                                        }
                                        PositionSensor {
                                          name "wrist3_sensor"
                                        }
                                      ]
                                      endPoint Solid {
                                        translation 0.000000 0.000000 0.117150
                                        children [
                                          DEF link6_visual CadShape {
                                            url "/home/dev/dev/webots/rbpodo_ros2/rbpodo_description/meshes/rb10_1300e/visual/link6.dae"
                                          }
                                          Solid {
                                            translation 0.000000 -0.115300 0.000000
                                            children [
                                              Group {
                                                children IS toolSlot
                                              }
                                            ]
                                            physics Physics {
                                            }
                                            boundingObject Box {
                                              size 0.01 0.01 0.01
                                            }
                                            name "tcp"
                                          }
                                        ]
                                        name "link6"
                                        boundingObject DEF link6 Mesh {
                                          url "/home/dev/dev/webots/rbpodo_ros2/rbpodo_description/meshes/rb10_1300e/collision/link6.stl"
                                        }
                                        physics Physics {
                                          density -1
                                          mass 0.406000
                                          centerOfMass [ -0.000210 -0.092540 -0.000292 ]
                                          inertiaMatrix [
                                            3.453140e-04 5.328730e-04 3.400210e-04
                                            5.730000e-07 6.610000e-07 -5.400000e-08
                                          ]
                                        }
                                      }
                                    }
                                  ]
                                  name "link5"
                                  boundingObject DEF link5 Mesh {
                                    url "/home/dev/dev/webots/rbpodo_ros2/rbpodo_description/meshes/rb10_1300e/collision/link5.stl"
                                  }
                                  physics Physics {
                                    density -1
                                    mass 2.061000
                                    centerOfMass [ -0.000093 -0.026434 -0.003233 ]
                                    inertiaMatrix [
                                      2.706437e-03 2.153592e-03 2.712272e-03
                                      1.120500e-05 -8.016000e-06 1.415280e-04
                                    ]
                                  }
                                }
                              }
                            ]
                            name "link4"
                            boundingObject DEF link4 Mesh {
                              url "/home/dev/dev/webots/rbpodo_ros2/rbpodo_description/meshes/rb10_1300e/collision/link4.stl"
                            }
                            physics Physics {
                              density -1
                              mass 2.062000
                              centerOfMass [ 0.000093 -0.113949 0.026461 ]
                              inertiaMatrix [
                                2.711100e-03 2.715407e-03 2.157043e-03
                                -8.022000e-06 1.120800e-05 1.442430e-04
                              ]
                            }
                          }
                        }
                      ]
                      name "link3"
                      boundingObject DEF link3 Mesh {
                        url "/home/dev/dev/webots/rbpodo_ros2/rbpodo_description/meshes/rb10_1300e/collision/link3.stl"
                      }
                      physics Physics {
                        density -1
                        mass 5.690000
                        centerOfMass [ -0.000048 -0.013885 0.325013 ]
                        inertiaMatrix [
                          3.120330e-01 3.112876e-01 1.139782e-02
                          9.298000e-06 1.169000e-05 5.331552e-03
                        ]
                      }
                    }
                  }
                ]
                name "link2"
                boundingObject DEF link2 Mesh {
                  url "/home/dev/dev/webots/rbpodo_ros2/rbpodo_description/meshes/rb10_1300e/collision/link2.stl"
                }
                physics Physics {
                  density -1
                  mass 15.610000
                  centerOfMass [ -0.000013 -0.155462 0.225241 ]
                  inertiaMatrix [
                    1.140651e+00 1.134399e+00 5.084907e-02
                    -1.304200e-05 -6.708400e-05 2.450788e-02
                  ]
                }
              }
            }
          ]
          name "link1"
          boundingObject DEF link1 Mesh {
            url "/home/dev/dev/webots/rbpodo_ros2/rbpodo_description/meshes/rb10_1300e/collision/link1.stl"
          }
          physics Physics {
            density -1
            mass 8.366000
            centerOfMass [ 0.000021 -0.007855 -0.042537 ]
            inertiaMatrix [
              2.740365e-02 2.777057e-02 2.614021e-02
              -5.926000e-06 -1.011900e-05 3.030512e-03
            ]
          }
        }
      }
    ]
    name IS name
    boundingObject DEF link0 Mesh {
      url "/home/dev/dev/webots/rbpodo_ros2/rbpodo_description/meshes/rb10_1300e/collision/link0.stl"
    }
    physics Physics {
    }
  }
}
